Workbook

Sheet ENEL
A1: Consolidado | B1: 40543 | C1: 40908 | D1: 41274 | E1: 41639 | F1: 42004 | G1: 42369 | H1: 42735 | I1: 43100 | J1: 43465 | K1: 43830 | L1: 44196 | M1: 44561 | N1: 44926 | O1: 45291 | P1: 45382
A2: ACTIVO
A3: Activo total | B3: 1489274149 | C3: 1558014006 | D3: 1695255205 | E3: 2256949998 | F3: 3035795403 | G3: 3262953316 | H3: 3480439534 | I3: 3529040173 | J3: 3964215271 | K3: 5169493602 | L3: 4888444532 | M3: 5418228373 | N3: 5595346439 | O3: 5698687722 | P3: 5998205421
A4: Activo Corriente | B4: 379676583 | C4: 365735174 | D4: 422837752 | E4: 568284929 | F4: 881440823 | G4: 694263548 | H4: 767898036 | I4: 744945928 | J4: 810596112 | K4: 1350183140 | L4: 1376958931 | M4: 1297379813 | N4: 1484646595 | O4: 1596064579 | P4: 1578145345
A5: Total de activos corrientes distintos de los activo o grupos de activos para su disposicion clasificados como mantenidos para la venta o como mantenidos para distribuir a los propietarios | B5: 379676583 | C5: 365735174 | D5: 422837752 | E5: 568284929 | F5: 881440823 | G5: 694263548 | H5: 767898036 | I5: 744945928 | J5: 810596112 | K5: 1316112040 | L5: 1362814034 | M5: 1297379813 | N5: 1358940312 | O5: 1592123674 | P5: 1573337275
A6: Efectivo | B6: 75272215 | C6: 23064067 | D6: 53876890 | E6: 19250402 | F6: 378919376 | G6: 136492472 | H6: 110914830 | I6: 145646465 | J6: 72748250 | K6: 447411760 | L6: 202481237 | M6: 108604768 | N6: 186542396 | O6: 530862387 | P6: 284520869
A7: Otros activos financieros corrientes | B7: 870798 | C7: 5407220 | D7: 1277781 | E7: 15429775 | F7: 13146216 | G7: 23819813 | H7: 4765731 | I7: 2118672 | J7: 17161830 | K7: 162710301 | L7: 389290088 | M7: 326830155 | N7: 167147402 | O7: 170887333 | P7: 372506338
A8: Otros activos no financieros corrientes | B8: 13145025 | C8: 16754397 | D8: 15893854 | E8: 20280834 | F8: 28790192 | G8: 27519924 | H8: 28565561 | I8: 33994053 | J8: 108926269 | K8: 88438713 | L8: 85956936 | M8: 95306980 | N8: 108416636 | O8: 126041006 | P8: 125675223
A9: Cuentas por cobrar corrientes | B9: 236011842 | C9: 251229640 | D9: 276768958 | E9: 326740821 | F9: 300591179 | G9: 308517488 | H9: 330626210 | I9: 346455962 | J9: 438739769 | K9: 508571105 | L9: 489258436 | M9: 620457323 | N9: 645453025 | O9: 633257358 | P9: 642310192
A10: Cuentas por cobrar a entidades relacionadas, corrientes | B10: 469192 | C10: 722752 | D10: 379554 | E10: 521772 | F10: 492035 | G10: 698417 | H10: 971320 | I10: 414501 | J10: 389434 | K10: 464522 | L10: 294621 | M10: 210440 | N10: 696046 | O10: 628381 | P10: 405008
A11: Inventarios corrientes | B11: 36799196 | C11: 63091800 | D11: 66357874 | E11: 150457167 | F11: 107121667 | G11: 94434998 | H11: 91416726 | I11: 96928834 | J11: 120229703 | K11: 82615111 | L11: 77736315 | M11: 121126311 | N11: 120441247 | O11: 107545480 | P11: 121357956
A12: Activos por impuestos corrientes, corrientes | B12: 17108315 | C12: 5465298 | D12: 8282841 | E12: 35604158 | F12: 52380158 | G12: 102780436 | H12: 200637658 | I12: 119387441 | J12: 52400857 | K12: 25900528 | L12: 117796401 | M12: 24843836 | N12: 130243560 | O12: 22901729 | P12: 26561689
A13: Activos no corrientes o grupos de activos para su disposicion clasificados como mantenidos para la venta o como mantenidos para distribuir a los propietarios | B13: 0 | C13: 0 | D13: 0 | E13: 0 | F13: 0 | G13: 0 | H13: 0 | I13: 0 | J13: 0 | K13: 34071100 | L13: 14144897 | M13: 0 | N13: 125706283 | O13: 3940905 | P13: 4808070
A14: Activo no Corriente | B14: 1109597566 | C14: 1192278832 | D14: 1272417453 | E14: 1688665069 | F14: 2154354580 | G14: 2568689768 | H14: 2712541498 | I14: 2784094245 | J14: 3153619159 | K14: 3819310462 | L14: 3511485601 | M14: 4120848560 | N14: 4110699844 | O14: 4102623143 | P14: 4420060076
... A25: Propiedad de inversion | B25: 0 | C25: 0 | D25: 0 | E25: 0 | F25: 0 | G25: 0 | H25: 0 | I25: 0 | J25: 0 | K25: 0 | L25: 0 | M25: 0 | N25: 0 | O25: 0 | P25: 0
A26: Activos por derechos de uso | B26: - | C26: 0 | D26: 0 | E26: 0 | F26: 0 | G26: 0 | H26: 0 | I26: 0 | J26: 0 | K26: 0 | L26: 362410839 | M26: 442122455 | N26: 472818691 | O26: 485851073 | P26: 504591654
A27: Activos por impuestos corrientes, no corrientes | B27: 0 | C27: 0 | D27: 0 | E27: 0 | F27: 0 | G27: 0 | H27: 0 | I27: 111376114 | J27: 2366841 | K27: 995171 | L27: 1078992 | M27: 640498 | N27: 1593767 | O27: 0 | P27: 0
A28: Activos por impuestos diferidos | B28: 39853167 | C28: 42866597 | D28: 65408124 | E28: 159987349 | F28: 238069845 | G28: 332969737 | H28: 384574176 | I28: 402576318 | J28: 494804455 | K28: 682381758 | L28: 634767525 | M28: 688472867 | N28: 823241988 | O28: 730737943 | P28: 781805301
A29: Total activos servicios bancarios | B29: 0 | C29: 0 | D29: 0 | E29: 0 | F29: 0 | G29: 0 | H29: 0 | I29: 0 | J29: 0 | K29: 0 | L29: 0 | M29: 0 | N29: 0 | O29: 0 | P29: 0
A31: PASIVO
A32: Pasivo + patrimonio neto | B32: 1489274149 | C32: 1558014006 | D32: 1695255205 | E32: 2256949998 | F32: 3035795403 | G32: 3262953316 | H32: 3480439534 | I32: 3529040173 | J32: 3964215271 | K32: 5169493602 | L32: 4888444532 | M32: 5418228373 | N32: 5595346439 | O32: 5698687722 | P32: 5998205421
A33: Pasivo total | B33: 767899626 | C33: 784936915 | D33: 881248684 | E33: 1375864886 | F33: 2079450541 | G33: 2307606436 | H33: 2218566793 | I33: 2290689003 | J33: 2597793309 | K33: 3560819204 | L33: 3379954105 | M33: 3915183006 | N33: 4040830663 | O33: 4023234762 | P33: 4190615794
A34: Pasivo Corriente | B34: 376371289 | C34: 394261450 | D34: 439322720 | E34: 515270360 | F34: 586386773 | G34: 585028258 | H34: 576051414 | I34: 623404767 | J34: 658742932 | K34: 891001450 | L34: 814156775 | M34: 1159502396 | N34: 1132020070 | O34: 1336992696 | P34: 1341385602
A35: Total de pasivos corrientes distintos de los pasivos incluidos en grupos de activos para su disposicion clasificados como mantenidos para la venta | B35: 376371289 | C35: 394261450 | D35: 439322720 | E35: 515270360 | F35: 586386773 | G35: 585028258 | H35: 576051414 | I35: 623404767 | J35: 658742932 | K35: 891001450 | L35: 814156775 | M35: 1159502396 | N35: 1132020070 | O35: 1336992696 | P35: 1341385602
A36: Otros pasivos financieros corrientes | B36: 14570686 | C36: 18584041 | D36: 28047529 | E36: 27243106 | F36: 20772473 | G36: 21736406 | H36: 24867284 | I36: 36540044 | J36: 20617883 | K36: 28813909 | L36: 22733634 | M36: 196857268 | N36: 275135592 | O36: 337854552 | P36: 333701865
A37: Pasivos por arrendamientos a corto plazo | B37: - | C37: 0 | D37: 0 | E37: 0 | F37: 0 | G37: 0 | H37: 0 | I37: 0 | J37: 0 | K37: 0 | L37: 75453147 | M37: 105314134 | N37: 109048285 | O37: 120979892 | P37: 126171946
A38: Provedores corrientes | B38: 319275469 | C38: 326224772 | D38: 373510494 | E38: 466529349 | F38: 529009412 | G38: 525128910 | H38: 505044060 | I38: 545150721 | J38: 553734579 | K38: 729338168 | L38: 662449107 | M38: 746239147 | N38: 694816615 | O38: 791220467 | P38: 756695389
A39: Cuentas por pagar a entidades relacionadas, corrientes | B39: 0 | C39: 0 | D39: 0 | E39: 0 | F39: 0 | G39: 0 | H39: 0 | I39: 0 | J39: 298309 | K39: 170385 | L39: 332181 | M39: 607794 | N39: 813773 | O39: 2509437 | P39: 3064738
A40: Otras provisiones a corto plazo | B40: 689270 | C40: 578262 | D40: 1635708 | E40: 153974 | F40: 180492 | G40: 3435395 | H40: 5161827 | I40: 7369584 | J40: 8446048 | K40: 1841742 | L40: 1479547 | M40: 1539643 | N40: 2111012 | O40: 3837218 | P40: 5138266
A41: Pasivos por impuestos corrientes, corrientes | B41: 201105 | C41: 7951010 | D41: 5718341 | E41: 1346165 | F41: 12866595 | G41: 5992038 | H41: 4869489 | I41: 355884 | J41: 43407612 | K41: 99275308 | L41: 14700058 | M41: 57204467 | N41: 15177415 | O41: 46692235 | P41: 82905491
A42: Provisiones corrientes por beneficios a los empleados | B42: 0 | C42: 0 | D42: 0 | E42: 0 | F42: 0 | G42: 0 | H42: 0 | I42: 0 | J42: 0 | K42: 0 | L42: 0 | M42: 0 | N42: 0 | O42: 0 | P42: 0
A43: Otros pasivos no financieros corrientes | B43: 41634759 | C43: 40923365 | D43: 30410648 | E43: 19997766 | F43: 23557801 | G43: 28735509 | H43: 36108754 | I43: 33988534 | J43: 32238501 | K43: 31561938 | L43: 37009101 | M43: 51739943 | N43: 34917378 | O43: 33898895 | P43: 33707907
A44: Pasivos incluidos en grupos de activos para su disposicion clasificados como mantenidos para la venta | B44: 0 | C44: 0 | D44: 0 | E44: 0 | F44: 0 | G44: 0 | H44: 0 | I44: 0 | J44: 0 | K44: 0 | L44: 0 | M44: 0 | N44: 0 | O44: 0 | P44: 0
A45: Pasivo no Corriente | B45: 391528337 | C45: 390675465 | D45: 441925964 | E45: 860594526 | F45: 1493063768 | G45: 1722578178 | H45: 1642515379 | I45: 1667284236 | J45: 1939050377 | K45: 2669817754 | L45: 2565797330 | M45: 2755680610 | N45: 2908810593 | O45: 2686242066 | P45: 2849230192
A46: Otros pasivos financieros no corrientes | B46: 350331042 | C46: 353504014 | D46: 407736898 | E46: 813151112 | F46: 1434258466 | G46: 1654135122 | H46: 1576910775 | I46: 1590913982 | J46: 1794895669 | K46: 1969001930 | L46: 1856453965 | M46: 1935510606 | N46: 1945802091 | O46: 1775723807 | P46: 1910809618
A47: Pasivos por arrendamientos a largo plazo | B47: - | C47: 0 | D47: 0 | E47: 0 | F47: 0 | G47: 0 | H47: 0 | I47: 0 | J47: 0 | K47: 0 | L47: 428773709 | M47: 486102565 | N47: 500043082 | O47: 471903079 | P47: 487983377
A48: Acreedores comerciales y otras cuentas a pagar no corrientes | B48: 0 | C48: 0 | D48: 0 | E48: 0 | F48: 0 | G48: 0 | H48: 0 | I48: 0 | J48: 0 | K48: 432945770 | L48: 0 | M48: 0 | N48: 0 | O48: 0 | P48: 0
A49: Cuentas por pagar a entidades relacionadas, no corrientes | B49: 0 | C49: 0 | D49: 0 | E49: 0 | F49: 0 | G49: 0 | H49: 0 | I49: 0 | J49: 0 | K49: 0 | L49: 0 | M49: 0 | N49: 0 | O49: 0 | P49: 0
A50: Otras provisiones a largo plazo | B50: 4001616 | C50: 5123356 | D50: 5869233 | E50: 13370970 | F50: 19596432 | G50: 28582453 | H50: 34222292 | I50: 36481730 | J50: 44054481 | K50: 37285161 | L50: 37718865 | M50: 40770581 | N50: 47636807 | O50: 53255027 | P50: 55674624
A51: Pasivo por impuestos diferidos | B51: 21345618 | C51: 11708289 | D51: 9093058 | E51: 19859855 | F51: 19989741 | G51: 19922788 | H51: 17821387 | I51: 22032668 | J51: 82345876 | K51: 204507336 | L51: 210225420 | M51: 260925087 | N51: 379612964 | O51: 179801727 | P51: 191799156
...

Sheet Análisis
A1: LIQUIDEZ
B2: 2010 | C2: 2011 | D2: 2012 | E2: 2013 | F2: 2014 | G2: 2015 | H2: 2016 | I2: 2017 | J2: 2018 | K2: 2019 | L2: 2020 | M2: 2021 | N2: 2022 | O2: 2023
A3: Razón Corriente | B3: =ENEL!B4/ENEL!B34 -> 1.008782 | C3: =ENEL!C4/ENEL!C34 -> 0.9276463 | D3: =ENEL!D4/ENEL!D34 -> 0.9624764 | E3: =ENEL!E4/ENEL!E34 -> 1.1028869 | F3: =ENEL!F4/ENEL!F34 -> 1.5031731 | G3: =ENEL!G4/ENEL!G34 -> 1.186718 | H3: =ENEL!H4/ENEL!H34 -> 1.3330373 | I3: =ENEL!I4/ENEL!I34 -> 1.1949635 | ... O3: =ENEL!O4/ENEL!O34 -> 1.1937721
A4: Liquidez Real | B4: =(ENEL!B4-(ENEL!B11+ENEL!B12 + ENEL!B13))/ENEL!B34 -> 0.8655524 | C4: =(ENEL!C4-(ENEL!C11+ENEL!C12 + ENEL!C13))/ENEL!C34 -> 0.7537589 | D4: =(ENEL!D4-(ENEL!D11+ENEL!D12 + ENEL!D13))/ENEL!D34 -> 0.79257689 | E4: =(ENEL!E4-(ENEL!E11+ENEL!E12 + ENEL!E13))/ENEL!E34 -> 0.74179234 | F4: =(ENEL!F4-(ENEL!F11+ENEL!F12 + ENEL!F13))/ENEL!F34 -> 1.2311652 | G4: =(ENEL!G4-(ENEL!G11+ENEL!G12 + ENEL!G13))/ENEL!G34 -> 0.84961386 | H4: =(ENEL!H4-(ENEL!H11+ENEL!H12 + ENEL!H13))/ENEL!H34 -> 0.82604372 | I4: =(ENEL!I4-(ENEL!I11+ENEL!I12 + ENEL!I13))/ENEL!I34 -> 0.84797178 | ... O4: =(ENEL!O4-(ENEL!O11+ENEL!O12 + ENEL!O13))/ENEL!O34 -> 1.0932569
A5: Prueba Ácida | B5: =(ENEL!B4-ENEL!B11)/ENEL!B34 -> 0.91100835 | C5: =(ENEL!C4-ENEL!C11)/ENEL!C34 -> 0.76762101 | D5: =(ENEL!D4-ENEL!D11)/ENEL!D34 -> 0.81143055 | E5: =(ENEL!E4-ENEL!E11)/ENEL!E34 -> 0.81089035 | F5: =(ENEL!F4-ENEL!F11)/ENEL!F34 -> 1.3204922 | G5: =(ENEL!G4-ENEL!G11)/ENEL!G34 -> 1.0252984 | H5: =(ENEL!H4-ENEL!H11)/ENEL!H34 -> 1.1743419 | I5: =(ENEL!I4-ENEL!I11)/ENEL!I34 -> 1.0394805 | ... O5: =(ENEL!O4-ENEL!O11)/ENEL!O34 -> 1.1133338
A26: ENDEUDAMIENTO
A27: Año | B27: 2010 | C27: 2011 | D27: 2012 | E27: 2013 | F27: 2014 | G27: 2015 | H27: 2016 | I27: 2017 | J27: 2018 | K27: 2019 | L27: 2020 | M27: 2021 | N27: 2022 | O27: 2023
A28: Razón de Deuda | B28: =ENEL!B33/ENEL!B3 -> 0.51562006 | C28: =ENEL!C33/ENEL!C3 -> 0.50380607 | D28: =ENEL!D33/ENEL!D3 -> 0.51983246 | E28: =ENEL!E33/ENEL!E3 -> 0.60961248 | F28: =ENEL!F33/ENEL!F3 -> 0.68497717 | G28: =ENEL!G33/ENEL!G3 -> 0.70721405 | H28: =ENEL!H33/ENEL!H3 -> 0.63743868 | I28: =ENEL!I33/ENEL!I3 -> 0.64909689 | ... O28: =ENEL!O33/ENEL!O3 -> 0.7059932
A29: Razón Deuda CP | B29: =ENEL!B34/ENEL!B3 -> 0.25272129 | C29: =ENEL!C34/ENEL!C3 -> 0.25305385 | D29: =ENEL!D34/ENEL!D3 -> 0.25914843 | E29: =ENEL!E34/ENEL!E3 -> 0.22830384 | F29: =ENEL!F34/ENEL!F3 -> 0.19315754 | G29: =ENEL!G34/ENEL!G3 -> 0.17929409 | H29: =ENEL!H34/ENEL!H3 -> 0.16551111 | I29: =ENEL!I34/ENEL!I3 -> 0.17664995 | ... O29: =ENEL!O34/ENEL!O3 -> 0.23461414
A30: Leverage Financiero | B30: =ENEL!B33/ENEL!B56 -> 1.0644951 | C30: =ENEL!C33/ENEL!C56 -> 1.0153411 | D30: =ENEL!D33/ENEL!D56 -> 1.0826064 | E30: =ENEL!E33/ENEL!E56 -> 1.5615573 | F30: =ENEL!F33/ENEL!F56 -> 2.1743731 | G30: =ENEL!G33/ENEL!G56 -> 2.4154645 | H30: =ENEL!H33/ENEL!H56 -> 1.7581541 | I30: =ENEL!I33/ENEL!I56 -> 1.8497895 | ... O30: =ENEL!O33/ENEL!O56 -> 2.4012818
A31: Cobertura Total | B31: 1.4284511 | C31: 1.5993465 | D31: 1.4804265 | E31: 1.0160561 | F31: 0.68221925 | G31: 0.64504753 | H31: 0.76089466 | I31: 0.758164 | J31: 0.75317701 | K31: 1.0044206 | L31: 0.97205794 | M31: 0.92775907 | N31: 1.5807347 | O31: 0.95091404
A32: Cobertura G.F. | B32: =(ENEL!B128+ENEL!B113)/ENEL!B113 -> 18.470408 | C32: =(ENEL!C128+ENEL!C113)/ENEL!C113 -> 18.523513 | D32: =(ENEL!D128+ENEL!D113)/ENEL!D113 -> 13.210646 | E32: =(ENEL!E128+ENEL!E113)/ENEL!E113 -> 8.0526786 | F32: =(ENEL!F128+ENEL!F113)/ENEL!F113 -> 2.022039 | G32: =(ENEL!G128+ENEL!G113)/ENEL!G113 -> 0.98447418 | H32: =(ENEL!H128+ENEL!H113)/ENEL!H113 -> 1.4154377 | I32: =(ENEL!I128+ENEL!I113)/ENEL!I113 -> 1.5423754 | ... O32: =(ENEL!O128+ENEL!O113)/ENEL!O113 -> 1.7847109
A33: COBERTURA
B34: 2010 | C34: 2011 | D34: 2012 | E34: 2013 | F34: 2014 | G34: 2015 | H34: 2016 | I34: 2017 | J34: 2018 | K34: 2019 | L34: 2020 | M34: 2021 | N34: 2022 | O34: 2023 | P34: 2024
A36: Cobertura Total | B36: =(ENEL!B128+ENEL!B113+ENEL!B122+ENEL!B106-ENEL!B107)/(ENEL!B113+ENEL!B38) -> 1.4284511 | C36: =(ENEL!C128+ENEL!C113+ENEL!C122+ENEL!C106-ENEL!C107)/(ENEL!C113+ENEL!C38) -> 1.5993465 | D36: =(ENEL!D128+ENEL!D113+ENEL!D122+ENEL!D106-ENEL!D107)/(ENEL!D113+ENEL!D38) -> 1.4804265 | E36: =(ENEL!E128+ENEL!E113+ENEL!E122+ENEL!E106-ENEL!E107)/(ENEL!E113+ENEL!E38) -> 1.0160561 | F36: =(ENEL!F128+ENEL!F113+ENEL!F122+ENEL!F106-ENEL!F107)/(ENEL!F113+ENEL!F38) -> 0.68221925 | G36: =(ENEL!G128+ENEL!G113+ENEL!G122+ENEL!G106-ENEL!G107)/(ENEL!G113+ENEL!G38) -> 0.64504753 | H36: =(ENEL!H128+ENEL!H113+ENEL!H122+ENEL!H106-ENEL!H107)/(ENEL!H113+ENEL!H38) -> 0.76089466 | I36: =(ENEL!I128+ENEL!I113+ENEL!I122+ENEL!I106-ENEL!I107)/(ENEL!I113+ENEL!I38) -> 0.758164 | ... P36: =(ENEL!P128+ENEL!P113+ENEL!P122+ENEL!P106-ENEL!P107)/(ENEL!P113+ENEL!P38) -> 0.2132231
L44: Ok normal
A56: EFICIENCIA
B57: 2010 | C57: 2011 | D57: 2012 | E57: 2013 | F57: 2014 | G57: 2015 | H57: 2016 | I57: 2017 | J57: 2018 | K57: 2019 | L57: 2020 | M57: 2021 | N57: 2022 | O57: 2023 | P57: 2024
L67: por qué? | M67: inv de act o - ixv
L68: aumento de activos
A81: RENTABILIDAD
A82: Año | B82: 2010 | C82: 2011 | D82: 2012 | E82: 2013 | F82: 2014 | G82: 2015 | H82: 2016 | I82: 2017 | J82: 2018 | K82: 2019 | L82: 2020 | M82: 2021 | N82: 2022 | O82: 2023
A83: Rotación de Activos | B83: =ENEL!B100/ENEL!B3 -> 0.72759951 | C83: =ENEL!C100/ENEL!C3 -> 0.78997894 | D83: =ENEL!D100/ENEL!D3 -> 0.84359906 | E83: =ENEL!E100/ENEL!E3 -> 0.72149383 | F83: =ENEL!F100/ENEL!F3 -> 0.54129715 | G83: =ENEL!G100/ENEL!G3 -> 0.54693172 | H83: =ENEL!H100/ENEL!H3 -> 0.53662678 | I83: =ENEL!I100/ENEL!I3 -> 0.55059481 | ... O83: =ENEL!O100/ENEL!O3 -> 0.43408104
A84: Margen Operacional | B84: =(ENEL!B100-ENEL!B105-ENEL!B108)/ENEL!B100 -> 0.43195256 | C84: =(ENEL!C100-ENEL!C105-ENEL!C108)/ENEL!C100 -> 0.43606978 | D84: =(ENEL!D100-ENEL!D105-ENEL!D108)/ENEL!D100 -> 0.39970055 | E84: =(ENEL!E100-ENEL!E105-ENEL!E108)/ENEL!E100 -> 0.30700561 | F84: =(ENEL!F100-ENEL!F105-ENEL!F108)/ENEL!F100 -> 0.24151309 | G84: =(ENEL!G100-ENEL!G105-ENEL!G108)/ENEL!G100 -> 0.22414614 | H84: =(ENEL!H100-ENEL!H105-ENEL!H108)/ENEL!H100 -> 0.24269254 | I84: =(ENEL!I100-ENEL!I105-ENEL!I108)/ENEL!I100 -> 0.24355417 | ... O84: =(ENEL!O100-ENEL!O105-ENEL!O108)/ENEL!O100 -> 0.31384169
A85: Margen Neto | B85: =ENEL!B128/ENEL!B100 -> 0.15962715 | C85: =ENEL!C128/ENEL!C100 -> 0.14686945 | D85: =ENEL!D128/ENEL!D100 -> 0.11697943 | E85: =ENEL!E128/ENEL!E100 -> 0.09025268 | F85: =ENEL!F128/ENEL!F100 -> 0.034364768 | G85: =ENEL!G128/ENEL!G100 -> -0.00061749926 | H85: =ENEL!H128/ENEL!H100 -> 0.018288887 | I85: =ENEL!I128/ENEL!I100 -> 0.022340685 | ... O85: =ENEL!O128/ENEL!O100 -> 0.03593186
A86: ROA | B86: =B85*B83 -> 0.11614464 | C86: =C85*C83 -> 0.11602377 | D86: =D85*D83 -> 0.098683735 | E86: =E85*E83 -> 0.065116752 | F86: =F85*F83 -> 0.018601551 | G86: =G85*G83 -> -0.00033772993 | H86: =H85*H83 -> 0.0098143064 | I86: =I85*I83 -> 0.012300665 | ... O86: =O85*O83 -> 0.015597339
A87: ROA(2) | B87: =(ENEL!B121+ENEL!B113)/ENEL!B3 -> 0.13930961 | C87: =(ENEL!C121+ENEL!C113)/ENEL!C3 -> 0.14739417 | D87: =(ENEL!D121+ENEL!D113)/ENEL!D3 -> 0.12525372 | E87: =(ENEL!E121+ENEL!E113)/ENEL!E3 -> 0.087620538 | F87: =(ENEL!F121+ENEL!F113)/ENEL!F3 -> 0.034162151 | G87: =(ENEL!G121+ENEL!G113)/ENEL!G3 -> 0.017498244 | H87: =(ENEL!H121+ENEL!H113)/ENEL!H3 -> 0.02538818 | I87: =(ENEL!I121+ENEL!I113)/ENEL!I3 -> 0.03004695 | ... O87: =(ENEL!O121+ENEL!O113)/ENEL!O3 -> 0.041038366
A88: ROA(3) | B88: =(ENEL!B121+ENEL!B113+ENEL!B106)/ENEL!B3 -> 0.29589561 | C88: =(ENEL!C121+ENEL!C113+ENEL!C106)/ENEL!C3 -> 0.32056249 | D88: =(ENEL!D121+ENEL!D113+ENEL!D106)/ENEL!D3 -> 0.30815834 | E88: =(ENEL!E121+ENEL!E113+ENEL!E106)/ENEL!E3 -> 0.19624764 | F88: =(ENEL!F121+ENEL!F113+ENEL!F106)/ENEL!F3 -> 0.11309872 | G88: =(ENEL!G121+ENEL!G113+ENEL!G106)/ENEL!G3 -> 0.10135647 | H88: =(ENEL!H121+ENEL!H113+ENEL!H106)/ENEL!H3 -> 0.11146476 | I88: =(ENEL!I121+ENEL!I113+ENEL!I106)/ENEL!I3 -> 0.11955221 | ... O88: =(ENEL!O121+ENEL!O113+ENEL!O106)/ENEL!O3 -> 0.12950477
A89: ROE | B89: =B86/(1-B28) -> 0.23978004 | C89: =C86/(1-C28) -> 0.23382747 | D89: =D86/(1-D28) -> 0.20551938 | E89: =E86/(1-E28) -> 0.16680029 | F89: =F86/(1-F28) -> 0.059048262 | G89: =G86/(1-G28) -> -0.0011535046 | H89: =H86/(1-H28) -> 0.02706937 | I89: =I86/(1-I28) -> 0.035054306 | ... O89: =O86/(1-O28) -> 0.053050947
O96: por qué disminuyo?
O97: por qué la brecha disminuye y dsps aumenta
O100: sciencedirect.com
O101: GARCH
C107: y esa subida? | I107: esa subida?
C108: ganancias extraordinarias | I108: ganancias extraordinarias
A111: Margen Op 2 | B111: =(ENEL!B110+IF(ENEL!B109<0, -ENEL!B109, ENEL!B109) -ENEL!B107 +ENEL!B106)/ENEL!B100 -> 0.43630304 | C111: =(ENEL!C110+IF(ENEL!C109<0, -ENEL!C109, ENEL!C109) -ENEL!C107 +ENEL!C106)/ENEL!C100 -> 0.44547258 | D111: =(ENEL!D110+IF(ENEL!D109<0, -ENEL!D109, ENEL!D109) -ENEL!D107 +ENEL!D106)/ENEL!D100 -> 0.40738194 | E111: =(ENEL!E110+IF(ENEL!E109<0, -ENEL!E109, ENEL!E109) -ENEL!E107 +ENEL!E106)/ENEL!E100 -> 0.31805197 | F111: =(ENEL!F110+IF(ENEL!F109<0, -ENEL!F109, ENEL!F109) -ENEL!F107 +ENEL!F106)/ENEL!F100 -> 0.26023549 | G111: =(ENEL!G110+IF(ENEL!G109<0, -ENEL!G109, ENEL!G109) -ENEL!G107 +ENEL!G106)/ENEL!G100 -> 0.22878846 | H111: =(ENEL!H110+IF(ENEL!H109<0, -ENEL!H109, ENEL!H109) -ENEL!H107 +ENEL!H106)/ENEL!H100 -> 0.25339838 | I111: =(ENEL!I110+IF(ENEL!I109<0, -ENEL!I109, ENEL!I109) -ENEL!I107 +ENEL!I106)/ENEL!I100 -> 0.24984522 | ... O111: =(ENEL!O110+IF(ENEL!O109<0, -ENEL!O109, ENEL!O109) -ENEL!O107 +ENEL!O106)/ENEL!O100 -> 0.37479268
A114: VALORES EN LIBRO
A115: UDI | B115: =ENEL!B128 -> 172971209 | C115: =ENEL!C128 -> 180766659 | D115: =ENEL!D128 -> 167294116 | E115: =ENEL!E128 -> 146965254 | F115: =ENEL!F128 -> 56470502 | G115: =ENEL!G128 -> -1101997 | H115: =ENEL!H128 -> 34158100 | I115: =ENEL!I128 -> 43409541 | ... P115: =ENEL!P128 -> -20431517
A116: EVA | B116: =ENEL!B128-ENEL!B113-ENEL!B109 -> 164563515 | C116: =ENEL!C128-ENEL!C113-ENEL!C109 -> 171907944 | D116: =ENEL!D128-ENEL!D113-ENEL!D109 -> 153716083 | E116: =ENEL!E128-ENEL!E113-ENEL!E109 -> 123693559 | F116: =ENEL!F128-ENEL!F113-ENEL!F109 -> -4763869 | G116: =ENEL!G128-ENEL!G113-ENEL!G109 -> -72046891 | H116: =ENEL!H128-ENEL!H113-ENEL!H109 -> -48454399 | I116: =ENEL!I128-ENEL!I113-ENEL!I109 -> -36750996 | ... P116: =ENEL!P128-ENEL!P113-ENEL!P109 -> -47815460
B118: 2010 | C118: 2011 | D118: 2012 | E118: 2013 | F118: 2014 | G118: 2015 | H118: 2016 | I118: 2017 | J118: 2018 | K118: 2019 | L118: 2020 | M118: 2021 | N118: 2022 | O118: 2023 | P118: 2024
...

Sheet A plotear
B2: Ratio\Año | C2: 2010 | D2: 2011 | E2: 2012 | F2: 2013 | G2: 2014 | H2: 2015 | I2: 2016 | J2: 2017 | K2: 2018 | L2: 2019 | M2: 2020 | N2: 2021 | O2: 2022 | P2: 2023
B3: Razón Corriente | C3: 1.008782 | D3: 0.9276463 | E3: 0.9624764 | F3: 1.1028869 | G3: 1.5031731 | H3: 1.186718 | I3: 1.3330373 | J3: 1.1949635 | K3: 1.2305196 | L3: 1.5153546 | M3: 1.69127 | N3: 1.1189109 | O3: 1.311502 | P3: 1.1937721
B4: Liquidez Real | C4: 0.8655524 | D4: 0.7537589 | E4: 0.79257689 | F4: 0.74179234 | G4: 1.2311652 | H4: 0.84961386 | I4: 0.82604372 | J4: 0.84797178 | K4: 0.96845905 | L4: 1.3553248 | M4: 1.4337304 | N4: 0.99302051 | O4: 0.97900694 | P4: 1.0932569
B5: Prueba Ácida | C5: 0.91100835 | D5: 0.76762101 | E5: 0.81143055 | F5: 0.81089035 | G5: 1.3204922 | H5: 1.0252984 | I5: 1.1743419 | J5: 1.0394805 | K5: 1.0480058 | L5: 1.422633 | M5: 1.5957892 | N5: 1.0144468 | O5: 1.205107 | P5: 1.1133338
B10: Ratio\Año | C10: 2010 | D10: 2011 | E10: 2012 | F10: 2013 | G10: 2014 | H10: 2015 | I10: 2016 | J10: 2017 | K10: 2018 | L10: 2019 | M10: 2020 | N10: 2021 | O10: 2022 | P10: 2023
B11: Razón de Deuda | C11: 0.51562006 | D11: 0.50380607 | E11: 0.51983246 | F11: 0.60961248 | G11: 0.68497717 | H11: 0.70721405 | I11: 0.63743868 | J11: 0.64909689 | K11: 0.65531086 | L11: 0.68881393 | M11: 0.69141709 | N11: 0.72259468 | O11: 0.72217703 | P11: 0.7059932
B12: Razón Deuda CP | C12: 0.25272129 | D12: 0.25305385 | E12: 0.25914843 | F12: 0.22830384 | G12: 0.19315754 | H12: 0.17929409 | I12: 0.16551111 | J12: 0.17664995 | K12: 0.16617234 | L12: 0.17235759 | M12: 0.16654721 | N12: 0.21400028 | O12: 0.20231456 | P12: 0.23461414
B13: Leverage Financiero | C13: 1.0644951 | D13: 1.0153411 | E13: 1.0826064 | F13: 1.5615573 | G13: 2.1743731 | H13: 2.4154645 | I13: 1.7581541 | J13: 1.8497895 | K13: 1.9011648 | L13: 2.2135115 | M13: 2.2406202 | N13: 2.6048336 | O13: 2.5994144 | P13: 2.4012818
B14: Cobertura Total | C14: 1.4284511 | D14: 1.5993465 | E14: 1.4804265 | F14: 1.0160561 | G14: 0.68221925 | H14: 0.64504753 | I14: 0.76089466 | J14: 0.758164 | K14: 0.75317701 | L14: 1.0044206 | M14: 0.97205794 | N14: 0.92775907 | O14: 1.5807347 | P14: 0.95091404
B15: Cobertura G.F. | C15: 18.470408 | D15: 18.523513 | E15: 13.210646 | F15: 8.0526786 | G15: 2.022039 | H15: 0.98447418 | I15: 1.4154377 | J15: 1.5423754 | K15: 0.69613007 | L15: 2.5800911 | M15: 1.8237721 | N15: 1.6579602 | O15: 5.0176065 | P15: 1.7847109
B18: Ratio\Año | C18: 2010 | D18: 2011 | E18: 2012 | F18: 2013 | G18: 2014 | H18: 2015 | I18: 2016 | J18: 2017 | K18: 2018 | L18: 2019 | M18: 2020 | N18: 2021 | O18: 2022 | P18: 2023
B19: Rotación de Activos | C19: 0.72759951 | D19: 0.78997894 | E19: 0.84359906 | F19: 0.72149383 | G19: 0.54129715 | H19: 0.54693172 | I19: 0.53662678 | J19: 0.55059481 | K19: 0.4826111 | L19: 0.38278256 | M19: 0.42807977 | N19: 0.44797312 | O19: 0.45407071 | P19: 0.43408104
... B25: ROE | C25: 0.23978004 | D25: 0.23382747 | E25: 0.20551938 | F25: 0.16680029 | G25: 0.059048262 | H25: -0.0011535046 | I25: 0.02706937 | J25: 0.035054306 | K25: -0.017281698 | L25: 0.095825548 | M25: 0.055993891 | N25: 0.049882267 | O25: 0.29384541 | P25: 0.053050947
C31: 2010 | D31: 2011 | E31: 2012 | F31: 2013 | G31: 2014 | H31: 2015 | I31: 2016 | J31: 2017 | K31: 2018 | L31: 2019 | M31: 2020 | N31: 2021 | O31: 2022 | P31: 2023
B32: Ingresos por Venta | C32: 1083595141 | D32: 1230798252 | E32: 1430115702 | F32: 1628375505 | G32: 1643267385 | H32: 1784612663 | I32: 1867697070 | J32: 1943071198 | K32: 1913174282 | L32: 1978791988 | M32: 2092644232 | N32: 2427220678 | O32: 2540682904 | P32: 2473692310
B33: IxV con IPC | C33: =C32*(1+Análisis!B119) -> 1.8952079e+09 | D33: =D32*(1+Análisis!C119) -> 2.0615871e+09 | E33: =E32*(1+Análisis!D119) -> 2.3596909e+09 | F33: =F32*(1+Análisis!E119) -> 2.6086576e+09 | G33: =G32*(1+Análisis!F119) -> 2.5158424e+09 | H33: =H32*(1+Análisis!G119) -> 2.6180268e+09 | I33: =I32*(1+Análisis!H119) -> 2.6670714e+09 | J33: =J32*(1+Análisis!I119) -> 2.7125274e+09 | ... P33: =P32*(1+Análisis!O119) -> 2.5281135e+09
C38: 2010 | D38: 2011 | E38: 2012 | F38: 2013 | G38: 2014 | H38: 2015 | I38: 2016 | J38: 2017 | K38: 2018 | L38: 2019 | M38: 2020 | N38: 2021 | O38: 2022 | P38: 2023
B39: Patrimonio neto | C39: 721374523 | D39: 773077091 | E39: 814006521 | F39: 881085112 | G39: 956344862 | H39: 955346880 | I39: 1261872741 | J39: 1238351170 | K39: 1366421962 | L39: 1608674398 | M39: 1508490427 | N39: 1503045367 | O39: 1554515776 | P39: 1675452960
B40: =Ganancia (perdida) neta | C40: 172971209 | D40: 180766659 | E40: 167294116 | F40: 146965254 | G40: 56470502 | H40: -1101997 | I40: 34158100 | J40: 43409541 | K40: -23614092 | L40: 154152106 | M40: 84466248 | N40: 74975311 | O40: 456787332 | P40: 88884366
B41: ROE | C41: =C40/C39 -> 0.23978004 | D41: =D40/D39 -> 0.23382747 | E41: =E40/E39 -> 0.20551938 | F41: =F40/F39 -> 0.16680029 | G41: =G40/G39 -> 0.059048262 | H41: =H40/H39 -> -0.0011535046 | I41: =I40/I39 -> 0.02706937 | J41: =J40/J39 -> 0.035054306 | ... P41: =P40/P39 -> 0.053050947
B61: Indice\Año | C61: 2010 | D61: 2011 | E61: 2012 | F61: 2013 | G61: 2014 | H61: 2015 | I61: 2016 | J61: 2017 | K61: 2018 | L61: 2019 | M61: 2020 | N61: 2021 | O61: 2022 | P61: 2023
B62: UDI | C62: 172971209 | D62: 180766659 | E62: 167294116 | F62: 146965254 | G62: 56470502 | H62: -1101997 | I62: 34158100 | J62: 43409541 | K62: -23614092 | L62: 154152106 | M62: 84466248 | N62: 74975311 | O62: 456787332 | P62: 88884366
B63: EVA | C63: 164563515 | D63: 171907944 | E63: 153716083 | F63: 123693559 | G63: -4763869 | H63: -72046891 | I63: -48454399 | J63: -36750996 | K63: -101236277 | L63: -150682344 | M63: -59655058 | N63: -59785333 | O63: -201873034 | P63: -75710210
B65: Indice con IPC\IPC | C65: 0.749 | D65: 0.675 | E65: 0.65 | F65: 0.602 | G65: 0.531 | H65: 0.467 | I65: 0.428 | J65: 0.396 | K65: 0.362 | L65: 0.322 | M65: 0.284 | N65: 0.198 | O65: 0.062 | P65: 0.022
B66: UDI c/IPC | C66: 3.0252664e+08 | D66: 3.0278415e+08 | E66: 2.7603529e+08 | F66: 2.3543834e+08 | G66: 86456339 | H66: -1616629.6 | I66: 48777767 | J66: 60599719 | K66: -32162393 | L66: 2.0378908e+08 | M66: 1.0845466e+08 | N66: 89820423 | O66: 4.8510815e+08 | P66: 90839822
B67: EVA c/IPC | C67: 2.8782159e+08 | D67: 2.8794581e+08 | E67: 2.5363154e+08 | F67: 1.9815708e+08 | G67: -7293483.4 | H67: -1.0569279e+08 | I67: -69192882 | J67: -51304390 | K67: -1.3788381e+08 | L67: -1.9920206e+08 | M67: -76597094 | N67: -71622829 | O67: -2.1438916e+08 | P67: -77375835
